2024-01-14 17:24:31,944 - ERROR - Error processing vote: type object 'PrivateMessage' has no attribute 'receiver_id'
Traceback (most recent call last):
  File "/home/dmytro/project/private_messages/app/routers/private_messages.py", line 82, in web_private_endpoint
    await change_message(message_data.id, message_data, session, user)
  File "/home/dmytro/project/private_messages/app/routers/func_private.py", line 147, in change_message
    query = select(models.PrivateMessage).where(models.PrivateMessage.id == id_message, models.PrivateMessage.receiver_id == current_user.id)
AttributeError: type object 'PrivateMessage' has no attribute 'receiver_id'
2024-01-14 17:25:40,804 - ERROR - Error processing vote: 1 validation error for SocketUpdate
message
  Field required [type=missing, input_value={'id': 431, 'messages': '... тебе бачить'}, input_type=dict]
    For further information visit https://errors.pydantic.dev/2.4/v/missing
Traceback (most recent call last):
  File "/home/dmytro/project/private_messages/app/routers/private_messages.py", line 81, in web_private_endpoint
    message_data = schemas.SocketUpdate(**data['change_message'])
  File "/home/dmytro/project/private_messages/venv/lib/python3.10/site-packages/pydantic/main.py", line 164, in __init__
    __pydantic_self__.__pydantic_validator__.validate_python(data, self_instance=__pydantic_self__)
pydantic_core._pydantic_core.ValidationError: 1 validation error for SocketUpdate
message
  Field required [type=missing, input_value={'id': 431, 'messages': '... тебе бачить'}, input_type=dict]
    For further information visit https://errors.pydantic.dev/2.4/v/missing
2024-01-14 17:27:07,492 - ERROR - Error processing vote: module 'app.models' has no attribute 'PrivateMessages'
Traceback (most recent call last):
  File "/home/dmytro/project/private_messages/app/routers/private_messages.py", line 82, in web_private_endpoint
    await change_message(message_data.id, message_data, session, user)
  File "/home/dmytro/project/private_messages/app/routers/func_private.py", line 147, in change_message
    query = select(models.PrivateMessage).where(models.PrivateMessages.id == id_messages, models.PrivateMessage.recipient_id == current_user.id)
AttributeError: module 'app.models' has no attribute 'PrivateMessages'
2024-01-14 17:28:45,538 - ERROR - Error processing vote: 
Traceback (most recent call last):
  File "/home/dmytro/project/private_messages/app/routers/private_messages.py", line 82, in web_private_endpoint
    await change_message(message_data.id, message_data, session, user)
  File "/home/dmytro/project/private_messages/app/routers/func_private.py", line 152, in change_message
    raise HTTPException(status_code=status.HTTP_404_NOT_FOUND, detail="Message not found or you don't have permission to edit this message")
fastapi.exceptions.HTTPException
